Workbook

Sheet Dashboard
A2: Supply Chain Analytics Dashboard
A4: Market | B4: All | D4: Customer segment | E4: All
A6: Total Records | C6: Total Orders | E6: Gross Sales | G6: Total Profit | I6: Gross AOV | K6: Late Delivery %
A7: =SUMIFS('Dashboard Data'!$C$4:'Dashboard Data'!$C$27,'Dashboard Data'!$A$4:'Dashboard Data'!$A$27,$B$4,'Dashboard Data'!$B$4:'Dashboard Data'!$B$27,$E$4) -> 180519 | C7: =SUMIFS('Dashboard Data'!$D$4:'Dashboard Data'!$D$27,'Dashboard Data'!$A$4:'Dashboard Data'!$A$27,$B$4,'Dashboard Data'!$B$4:'Dashboard Data'!$B$27,$E$4) -> 65752 | E7: =SUMIFS('Dashboard Data'!$F$4:'Dashboard Data'!$F$27,'Dashboard Data'!$A$4:'Dashboard Data'!$A$27,$B$4,'Dashboard Data'!$B$4:'Dashboard Data'!$B$27,$E$4) -> 36784734 | G7: =SUMIFS('Dashboard Data'!$I$4:'Dashboard Data'!$I$27,'Dashboard Data'!$A$4:'Dashboard Data'!$A$27,$B$4,'Dashboard Data'!$B$4:'Dashboard Data'!$B$27,$E$4) -> 3966903 | I7: =IFERROR(SUMIFS('Dashboard Data'!$F$4:'Dashboard Data'!$F$27,'Dashboard Data'!$A$4:'Dashboard Data'!$A$27,$B$4,'Dashboard Data'!$B$4:'Dashboard Data'!$B$27,$E$4)/SUMIFS('Dashboard Data'!$D$4:'Dashboard Data'!$D$27,'Dashboard Data'!$A$4:'Dashboard Data'!$A$27,$B$4,'Dashboard Data'!$B$4:'Dashboard Data'!$B$27,$E$4),0) -> 559.44662 | K7: =IFERROR(SUMIFS('Dashboard Data'!$J$4:'Dashboard Data'!$J$27,'Dashboard Data'!$A$4:'Dashboard Data'!$A$27,$B$4,'Dashboard Data'!$B$4:'Dashboard Data'!$B$27,$E$4)/SUMIFS('Dashboard Data'!$C$4:'Dashboard Data'!$C$27,'Dashboard Data'!$A$4:'Dashboard Data'!$A$27,$B$4,'Dashboard Data'!$B$4:'Dashboard Data'!$B$27,$E$4),0) -> 0.54829132
A63: Key findings and recommended actions
A64: First Class is late on 95.27% of orders; reset the 1-day promise or improve carrier execution.
A65: The top 10 products generate 89.98% of gross sales; protect availability and supplier continuity for these SKUs.
A66: 21.15% of orders are loss-making; review discount and product-level margin rules.
A67: Customer segment late rates vary by only 0.35 percentage points; prioritize shipping mode and carrier fixes over segment-specific policies.

Sheet Monthly Trends
A2: Monthly and Yearly Performance
A3: Gross sales are before discounts; profit is based on net sales
A5: order_year_month | B5: records | C5: orders | D5: units | E5: gross_sales | F5: net_sales | G5: profit | H5: gross_aov | I5: profit_margin_net | J5: late_delivery_rate_row | K5: gross_sales_yoy | L5: profit_yoy | N5: Yearly summary
A6: 2015-01 | B6: 5322 | C6: 1787 | D6: 11854 | E6: 1051590.1 | F6: 945382.15 | G6: 111660.74 | H6: 588.47 | I6: 0.11811175 | J6: 0.54114994 | N6: order_year | O6: orders | P6: gross_sales | Q6: net_sales | R6: profit | S6: gross_aov | T6: gross_sales_yoy | U6: profit_yoy | V6: period_note
A7: 2015-02 | B7: 4729 | C7: 1585 | D7: 10438 | E7: 927009.88 | F7: 833012.42 | G7: 99140.66 | H7: 584.86 | I7: 0.11901462 | J7: 0.54853034 | N7: 2015 | O7: 20904 | P7: 12340831 | Q7: 11089543 | R7: 1318856.9 | S7: 590.36 | V7: Full year
A8: 2015-03 | B8: 5362 | C8: 1781 | D8: 12062 | E8: 1051253.7 | F8: 944050.1 | G8: 113778.21 | H8: 590.26 | I8: 0.12052137 | J8: 0.54755688 | N8: 2016 | O8: 20859 | P8: 12303817 | Q8: 11055997 | R8: 1310119.1 | S8: 589.86 | T8: -0.0029993207 | U8: -0.0066253056 | V8: Full year
A9: 2015-04 | B9: 5126 | C9: 1710 | D9: 11287 | E9: 1014463.3 | F9: 912004.39 | G9: 108083.68 | H9: 593.25 | I9: 0.11851224 | J9: 0.53843153 | N9: 2017 | O9: 21866 | P9: 11808436 | Q9: 10610910 | R9: 1304085.1 | S9: 540.04 | T9: -0.040262396 | U9: -0.0046056577 | V9: Full year
A10: 2015-05 | B10: 5357 | C10: 1776 | D10: 11902 | E10: 1050478.4 | F10: 943939.76 | G10: 112147.9 | H10: 591.49 | I10: 0.11880832 | J10: 0.55086802 | N10: 2018 | O10: 2123 | P10: 331650.11 | Q10: 297952.05 | R10: 33841.89 | S10: 156.22 | T10: -0.97191414 | U10: -0.97404932 | V10: January only
A11: 2015-06 | B11: 5134 | C11: 1725 | D11: 11203 | E11: 1024006.2 | F11: 920242.05 | G11: 110147.16 | H11: 593.63 | I11: 0.11969368 | J11: 0.54109856
A12: 2015-07 | B12: 5299 | C12: 1763 | D12: 11800 | E12: 1038081.2 | F12: 932936.78 | G12: 115624.06 | H12: 588.82 | I12: 0.12393558 | J12: 0.55463295
A13: 2015-08 | B13: 5273 | C13: 1762 | D13: 11612 | E13: 1029494.7 | F13: 925192.86 | G13: 117979.77 | H13: 584.28 | I13: 0.12751911 | J13: 0.55679879
A14: 2015-09 | B14: 5140 | C14: 1706 | D14: 11366 | E14: 1018338.6 | F14: 914522.36 | G14: 113467.94 | H14: 596.92 | I14: 0.12407345 | J14: 0.56692607
A15: 2015-10 | B15: 5302 | C15: 1775 | D15: 11703 | E15: 1049154.2 | F15: 943131.09 | G15: 101757.87 | H15: 591.07 | I15: 0.10789367 | J15: 0.54809506
A16: 2015-11 | B16: 5235 | C16: 1729 | D16: 11463 | E16: 1029120.2 | F16: 924602.56 | G16: 104427.36 | H16: 595.21 | I16: 0.11294297 | J16: 0.54269341
A17: 2015-12 | B17: 5371 | C17: 1805 | D17: 11790 | E17: 1057840.9 | F17: 950526.91 | G17: 110641.55 | H17: 586.06 | I17: 0.11640023 | J17: 0.54682554
A18: 2016-01 | B18: 5317 | C18: 1772 | D18: 11597 | E18: 1046308.2 | F18: 940283.62 | G18: 106780.95 | H18: 590.47 | I18: 0.11356249 | J18: 0.55576453 | K18: -0.0050227082 | L18: -0.043701931
A19: 2016-02 | B19: 4894 | C19: 1650 | D19: 10765 | E19: 968542.83 | F19: 870116.74 | G19: 86809.49 | H19: 587 | I19: 0.099767636 | J19: 0.54147936 | K19: 0.044803136 | L19: -0.12438055
A20: 2016-03 | B20: 5210 | C20: 1764 | D20: 11349 | E20: 1025853.1 | F20: 921487.72 | G20: 101259.99 | H20: 581.55 | I20: 0.10988751 | J20: 0.55758157 | K20: -0.02416217 | L20: -0.110023
A21: 2016-04 | B21: 5097 | C21: 1706 | D21: 11208 | E21: 1001211.6 | F21: 900492.91 | G21: 114976.62 | H21: 586.88 | I21: 0.12768187 | J21: 0.55228566 | K21: -0.01306277 | L21: 0.063774105
A22: 2016-05 | B22: 5302 | C22: 1763 | D22: 11603 | E22: 1029400.2 | F22: 924978.21 | G22: 110716.12 | H22: 583.89 | I22: 0.11969592 | J22: 0.55658242 | K22: -0.020065372 | L22: -0.012766891
A23: 2016-06 | B23: 5054 | C23: 1690 | D23: 11008 | E23: 1003059.5 | F23: 901448 | G23: 104196.07 | H23: 593.53 | I23: 0.11558744 | J23: 0.56846063 | K23: -0.020455561 | L23: -0.054028538
A24: 2016-07 | B24: 5305 | C24: 1758 | D24: 11652 | E24: 1045715.6 | F24: 939216.39 | G24: 119941.72 | H24: 594.83 | I24: 0.12770403 | J24: 0.51932139 | K24: 0.0073543671 | L24: 0.037342228
A25: 2016-08 | B25: 5334 | C25: 1766 | D25: 11683 | E25: 1048200.2 | F25: 942408.93 | G25: 110729.54 | H25: 593.54 | I25: 0.11749628 | J25: 0.55268091 | K25: 0.018169652 | L25: -0.061453163
A26: 2016-09 | B26: 5160 | C26: 1730 | D26: 11284 | E26: 1002397 | F26: 900371.62 | G26: 123384.71 | H26: 579.42 | I26: 0.13703754 | J26: 0.5498062 | K26: -0.015654479 | L26: 0.08739711
A27: 2016-10 | B27: 5398 | C27: 1776 | D27: 11936 | E27: 1048130.5 | F27: 941882.27 | G27: 116781.97 | H27: 590.16 | I27: 0.12398786 | J27: 0.54779548 | K27: -0.00097575738 | L27: 0.14764558
A28: 2016-11 | B28: 5210 | C28: 1721 | D28: 11493 | E28: 1047590.1 | F28: 941197.35 | G28: 109539.2 | H28: 608.71 | I28: 0.11638282 | J28: 0.5462572 | K28: 0.017947272 | L28: 0.048951156
A29: 2016-12 | B29: 5269 | C29: 1763 | D29: 11774 | E29: 1037408.2 | F29: 932112.88 | G29: 105002.69 | H29: 588.43 | I29: 0.11265019 | J29: 0.56063769 | K29: -0.019315486 | L29: -0.050965121
... A42: 2018-01 | B42: 2123 | C42: 2123 | D42: 2123 | E42: 331650.11 | F42: 297952.05 | G42: 33841.89 | H42: 156.22 | I42: 0.11358167 | J42: 0.56288271 | K42: -0.67791517 | L42: -0.70532257

Sheet Customer & Region
A2: Customer and Regional Performance
A3: Refreshable summary tables generated from the processed line-item dataset
A5: Customer segments
A6: customer_segment | B6: records | C6: orders | D6: units | E6: gross_sales | F6: net_sales | G6: discount | H6: profit | I6: gross_aov | J6: net_aov | K6: profit_margin_net | L6: late_delivery_rate_row
A7: Consumer | B7: 93504 | C7: 34119 | D7: 199234 | E7: 19095790 | F7: 17164278 | G7: 1931535.7 | H7: 2073487.7 | I7: 559.68 | J7: 503.07 | K7: 0.1208025 | L7: 0.5480835
A8: Corporate | B8: 54789 | C8: 19856 | D8: 116560 | E8: 11168407 | F8: 10030650 | G8: 1137770.7 | H8: 1202575 | I8: 562.47 | J8: 505.17 | K8: 0.11989004 | L8: 0.54722663
A9: Home Office | B9: 32226 | C9: 11777 | D9: 68285 | E9: 6520537.9 | F9: 5859474 | G9: 661072 | H9: 690840.34 | I9: 553.67 | J9: 497.54 | K9: 0.11790142 | L9: 0.5507044
A12: Markets
A13: market | B13: records | C13: orders | D13: units | E13: gross_sales | F13: net_sales | G13: discount | H13: profit | I13: gross_aov | J13: net_aov | K13: profit_margin_net | L13: late_delivery_rate_row
A14: Africa | B14: 11614 | C14: 3854 | D14: 25603 | E14: 2294452.9 | F14: 2061679.4 | G14: 232776.37 | H14: 252071.18 | I14: 595.34 | J14: 534.95 | K14: 0.12226498 | L14: 0.54589289
A15: Europe | B15: 50252 | C15: 18561 | D15: 105238 | E15: 10872397 | F15: 9769198.2 | G15: 1103210.8 | H15: 1169443 | I15: 585.77 | J15: 526.33 | K15: 0.11970716 | L15: 0.55207753
A16: LATAM | B16: 51594 | C16: 17181 | D16: 112942 | E16: 10277613 | F16: 9235762 | G16: 1041863.2 | H16: 1123321.6 | I16: 598.2 | J16: 537.56 | K16: 0.12162739 | L16: 0.54355158
A17: Pacific Asia | B17: 41260 | C17: 17577 | D17: 83680 | E17: 8273743.6 | F17: 7434262.6 | G17: 839493.31 | H17: 857753.44 | I17: 470.71 | J17: 422.95 | K17: 0.11537842 | L17: 0.55046049
A18: USCA | B18: 25799 | C18: 8579 | D18: 56616 | E18: 5066528.6 | F18: 4553499.9 | G18: 513034.82 | H18: 564313.78 | I18: 590.57 | J18: 530.77 | K18: 0.12392968 | L18: 0.54800574
A22: Order regions
A23: order_region | B23: records | C23: orders | D23: gross_sales | E23: net_sales | F23: profit | G23: gross_aov | H23: profit_margin_net | I23: late_delivery_rate_row
A24: Western Europe | B24: 27109 | C24: 10010 | D24: 5894380.7 | E24: 5296002.8 | F24: 625446.08 | G24: 588.85 | H24: 0.11809776 | I24: 0.55848611
A25: Central America | B25: 28341 | C25: 9396 | D25: 5665712 | E25: 5093849.7 | F25: 616341.57 | G25: 602.99 | H25: 0.1209972 | I25: 0.54754596
A26: South America | B26: 14935 | C26: 4979 | D26: 2960881.4 | E26: 2660243.7 | F26: 335154.4 | G26: 594.67 | H26: 0.12598635 | I26: 0.54308671
A27: Northern Europe | B27: 9792 | C27: 3716 | D27: 2155830.6 | E27: 1939362.4 | F27: 233450.6 | G27: 580.15 | H27: 0.12037492 | I27: 0.54044118
A28: Southern Europe | B28: 9431 | C28: 3543 | D28: 2047918.8 | E28: 1837525.8 | F28: 230829.23 | G28: 578.02 | H28: 0.12561959 | I28: 0.54384477
A29: Oceania | B29: 10148 | C29: 4362 | D29: 2016654.2 | E29: 1809996.5 | F29: 201478.02 | G29: 462.32 | H29: 0.11131404 | I29: 0.54020497
A30: Southeast Asia | B30: 9539 | C30: 4356 | D30: 1932495.5 | E30: 1738553.4 | F30: 211342.82 | G30: 443.64 | H30: 0.12156245 | I30: 0.5552993
A31: Caribbean | B31: 8318 | C31: 2806 | D31: 1651019.3 | E31: 1481668.7 | F31: 171825.64 | G31: 588.39 | H31: 0.11596765 | I31: 0.53077663
A32: West of USA | B32: 7993 | C32: 2667 | D32: 1571415.9 | E32: 1412253.6 | F32: 164940.66 | G32: 589.21 | H32: 0.11679252 | I32: 0.53959715
A33: South Asia | B33: 7731 | C33: 3335 | D33: 1553680.9 | E33: 1397364.6 | F33: 165703.9 | G33: 465.87 | H33: 0.11858316 | I33: 0.56266977
A34: Eastern Asia | B34: 7280 | C34: 3318 | D34: 1486401.3 | E34: 1334313.4 | F34: 147368.01 | G34: 447.98 | H34: 0.11044483 | I34: 0.54326923
A35: East of USA | B35: 6915 | C35: 2323 | D35: 1371112 | E35: 1231955.1 | F35: 156263.3 | G35: 590.23 | H35: 0.12684171 | I35: 0.55661605
... A46: Central Asia | B46: 553 | C46: 184 | D46: 109839.93 | E46: 97953.69 | F46: 13045.28 | G46: 596.96 | H46: 0.13317804 | I46: 0.55334539

Sheet Shipping
A2: Shipping and Delivery Performance
A3: Order-grain shipping metrics avoid line-count weighting
A5: Shipping modes
A6: shipping_mode | B6: orders | C6: gross_sales | D6: net_sales | E6: profit | F6: late_orders | G6: avg_actual_shipping_days | H6: avg_scheduled_shipping_days | I6: avg_shipping_variance_days | J6: late_delivery_rate_order | K6: gross_aov | L6: net_aov | M6: profit_margin_net
A7: First Class | B7: 10079 | C7: 5674369.7 | D7: 5100451 | E7: 643121.92 | F7: 9602 | G7: 2 | H7: 1 | I7: 1 | J7: 0.95267388 | K7: 562.99 | L7: 506.05 | M7: 0.12609119
A8: Second Class | B8: 12778 | C8: 7145444.7 | D8: 6416528.5 | E8: 750308.17 | F8: 9803 | G8: 4.0015652 | H8: 2 | I8: 2.0015652 | J8: 0.76717796 | K8: 559.2 | L8: 502.15 | M8: 0.11693366
A9: Same Day | B9: 3571 | C9: 1942528.5 | D9: 1745201.5 | E9: 203018.43 | F9: 1648 | G9: 0.48361803 | H9: 0 | I9: 0.48361803 | J9: 0.46149538 | K9: 543.97 | L9: 488.72 | M9: 0.11632951
A10: Standard Class | B10: 39324 | C10: 22022391 | D10: 19792221 | E10: 2370454.5 | F10: 14995 | G10: 3.9968976 | H10: 4 | I10: -0.0031024311 | J10: 0.3813193 | K10: 560.02 | L10: 503.31 | M10: 0.11976698
A14: Delivery status
A15: delivery_status | B15: orders | C15: gross_sales | D15: net_sales | E15: profit | F15: late_orders | G15: avg_actual_shipping_days | H15: avg_scheduled_shipping_days | I15: avg_shipping_variance_days | J15: late_delivery_rate_order | K15: gross_aov | L15: net_aov | M15: profit_margin_net
A16: Advance shipping | B16: 15127 | C16: 8518007.7 | D16: 7656338.7 | E16: 935225.28 | F16: 0 | G16: 2.496926 | H16: 4 | I16: -1.503074 | J16: 0 | K16: 563.1 | L16: 506.14 | M16: 0.12215046
A17: Late delivery | B17: 36048 | C17: 20126395 | D17: 18082555 | E17: 2140051.7 | F17: 36048 | G17: 4.0922659 | H17: 2.4741456 | I17: 1.6181203 | J17: 1 | K17: 558.32 | L17: 501.62 | M17: 0.11834896
A18: Shipping canceled | B18: 2855 | C18: 1570305.3 | D18: 1409737.3 | E18: 160482.34 | F18: 0 | G18: 3.4872154 | H18: 2.9033275 | I18: 0.58388792 | J18: 0 | K18: 550.02 | L18: 493.78 | M18: 0.11383847
A19: Shipping on time | B19: 11722 | C19: 6570026.4 | D19: 5905771 | E19: 731143.67 | F19: 0 | G19: 2.9812319 | H19: 2.9812319 | I19: 0 | J19: 0 | K19: 560.49 | L19: 503.82 | M19: 0.12380156

Sheet Products
A2: Product and Category Performance
A3: Rankings use gross sales; profitability uses net sales as the denominator
A5: Top 15 products by gross sales | M5: Bottom 10 products by profit
A6: product_id | B6: product_name | C6: category_name | D6: records | E6: orders | F6: units | G6: gross_sales | H6: net_sales | I6: profit | J6: profit_margin_net | K6: late_delivery_rate_row | M6: product_id | N6: product_name | O6: category_name | P6: records | Q6: orders | R6: units | S6: gross_sales | T6: net_sales | U6: profit | V6: profit_margin_net | W6: late_delivery_rate_row
A7: 1004 | B7: Field & Stream Sportsman 16 Gun Fire Safe | C7: Fishing | D7: 17325 | E7: 15164 | F7: 17325 | G7: 6929653.5 | H7: 6226935.1 | I7: 756220.76 | J7: 0.12144349 | K7: 0.54926407 | M7: 208 | N7: SOLE E35 Elliptical | O7: Strength Training | P7: 15 | Q7: 15 | R7: 15 | S7: 29999.85 | T7: 26409.85 | U7: -965.12 | V7: -0.036543941 | W7: 0.4
A8: 365 | B8: Perfect Fitness Perfect Rip Deck | C8: Cleats | D8: 24515 | E8: 20359 | F8: 73698 | G8: 4421143 | H8: 3973180.3 | I8: 493828.3 | J8: 0.12429043 | K8: 0.54958189 | M8: 860 | N8: Bushnell Pro X7 Jolt Slope Rangefinder | O8: Kids' Golf Clubs | P8: 11 | Q8: 8 | R8: 11 | S8: 6599.89 | T8: 6062.89 | U8: -255.95 | V8: -0.042215841 | W8: 0.54545455
A9: 957 | B9: Diamondback Women's Serene Classic Comfort Bi | C9: Camping & Hiking | D9: 13729 | E9: 12299 | F9: 13729 | G9: 4118425.4 | H9: 3700783.5 | I9: 427455.57 | J9: 0.11550407 | K9: 0.54534198 | M9: 60 | N9: SOLE E25 Elliptical | O9: Basketball | P9: 10 | Q9: 10 | R9: 10 | S9: 9999.9 | T9: 9414.9 | U9: -169.56 | V9: -0.018009751 | W9: 0.7
A10: 191 | B10: Nike Men's Free 5.0+ Running Shoe | C10: Cardio Equipment | D10: 12169 | E10: 11092 | F10: 36680 | G10: 3667633.2 | H10: 3295693.3 | I10: 379915.82 | J10: 0.11527645 | K10: 0.54474484 | M10: 203 | N10: GoPro HERO3+ Black Edition Camera | O10: Strength Training | P10: 32 | Q10: 32 | R10: 32 | S10: 12799.68 | T10: 11601.68 | U10: 245.63 | V10: 0.021171934 | W10: 0.65625
A11: 502 | B11: Nike Men's Dri-FIT Victory Golf Polo | C11: Women's Apparel | D11: 21035 | E11: 17869 | F11: 62956 | G11: 3147800 | H11: 2828708.5 | I11: 350421.03 | J11: 0.12388022 | K11: 0.54556691 | M11: 61 | N11: Diamondback Girls' Clarity 24 Hybrid Bike 201 | O11: Basketball | P11: 28 | Q11: 27 | R11: 28 | S11: 8399.72 | T11: 7624.22 | U11: 284.42 | V11: 0.0373048 | W11: 0.42857143
A12: 1073 | B12: Pelican Sunstream 100 Kayak | C12: Water Sports | D12: 15500 | E12: 13727 | F12: 15500 | G12: 3099845 | H12: 2785518 | I12: 324076.37 | J12: 0.1163433 | K12: 0.54787097 | M12: 311 | N12: Polar Loop Activity Tracker | O12: Kids' Golf Clubs | P12: 54 | Q12: 53 | R12: 54 | S12: 5937.3 | T12: 5335.32 | U12: 326.2 | V12: 0.061139725 | W12: 0.48148148
A13: 403 | B13: Nike Men's CJ Elite 2 TD Football Cleat | C13: Men's Footwear | D13: 22246 | E13: 18783 | F13: 22246 | G13: 2891757.5 | H13: 2598494.4 | I13: 311902.82 | J13: 0.12003213 | K13: 0.544862 | M13: 705 | N13: Cleveland Golf Women's 588 RTX CB Satin Chrom | O13: Golf Apparel | P13: 70 | Q13: 70 | R13: 70 | S13: 8399.3 | T13: 7538.3 | U13: 370.61 | V13: 0.049163605 | W13: 0.5
A14: 1014 | B14: O'Brien Men's Neoprene Life Vest | C14: Indoor/Outdoor Games | D14: 19298 | E14: 16623 | F14: 57803 | G14: 2888993.9 | H14: 2596454 | I14: 318451.43 | J14: 0.12264859 | K14: 0.54746606 | M14: 1348 | N14: CDs of rock | O14: CDs | P14: 271 | Q14: 271 | R14: 271 | S14: 3059.59 | T14: 2750.03 | U14: 383.85 | V14: 0.1395803 | W14: 0.5202952
A15: 627 | B15: Under Armour Girls' Toddler Spine Surge Runni | C15: Shop By Sport | D15: 10617 | E15: 9825 | F15: 31735 | G15: 1269082.6 | H15: 1140770.9 | I15: 126278.51 | J15: 0.11069576 | K15: 0.55241594 | M15: 303 | N15: Garmin Forerunner 910XT GPS Watch | O15: Kids' Golf Clubs | P15: 35 | Q15: 35 | R15: 35 | S15: 13999.65 | T15: 12593.65 | U15: 391.13 | V15: 0.031057716 | W15: 0.54285714
A16: 1351 | B16: Dell Laptop | C16: Computers | D16: 442 | E16: 442 | F16: 442 | G16: 663000 | H16: 595395 | I16: 69656.81 | J16: 0.1169926 | K16: 0.50678733 | M16: 127 | N16: Stiga Master Series ST3100 Competition Indoor | O16: Hockey | P16: 27 | Q16: 25 | R16: 27 | S16: 8909.73 | T16: 8154.03 | U16: 479.28 | V16: 0.058778297 | W16: 0.51851852
A17: 1349 | B17: Web Camera | C17: Cameras | D17: 592 | E17: 592 | F17: 592 | G17: 267607.68 | H17: 240496.68 | I17: 30289.8 | J17: 0.12594685 | K17: 0.58108108
A18: 1355 | B18: Lawn mower | C18: Garden | D18: 484 | E18: 484 | F18: 484 | G18: 257768.72 | H18: 231765.46 | I18: 33443.01 | J18: 0.14429678 | K18: 0.55785124
A19: 1350 | B19: Children's heaters | C19: Children's Clothing | D19: 652 | E19: 652 | F19: 652 | G19: 232829.2 | H19: 209268.38 | I19: 27178.1 | J19: 0.12987199 | K19: 0.53374233
A20: 1353 | B20: Porcelain crafts | C20: Crafts | D20: 484 | E20: 484 | F20: 484 | G20: 223356.32 | H20: 200704.87 | I20: 25531.17 | J20: 0.12720753 | K20: 0.55991736
A21: 1363 | B21: Summer dresses | C21: Women's Clothing | D21: 650 | E21: 650 | F21: 650 | G21: 140283 | H21: 126006.93 | I21: 19102.85 | J21: 0.15160158 | K21: 0.56461538
A25: Top 15 categories by gross sales
A26: category_name | B26: records | C26: orders | D26: units | E26: gross_sales | F26: net_sales | G26: discount | H26: profit | I26: gross_aov | J26: profit_margin_net | K26: late_delivery_rate_row
A27: Fishing | B27: 17325 | C27: 15164 | D27: 17325 | E27: 6929653.5 | F27: 6226935.1 | G27: 702728 | H27: 756220.76 | I27: 456.98 | J27: 0.12144349 | K27: 0.54926407
A28: Cleats | B28: 24551 | C28: 20386 | D28: 73734 | E28: 4431942.7 | F28: 3982856.5 | G28: 449091.67 | H28: 494636.92 | I28: 217.4 | J28: 0.1241915 | K28: 0.54971284
A29: Camping & Hiking | B29: 13729 | C29: 12299 | D29: 13729 | E29: 4118425.4 | F29: 3700783.5 | G29: 417649.5 | H29: 427455.57 | I29: 334.86 | J29: 0.11550407 | K29: 0.54534198
A30: Cardio Equipment | B30: 12487 | C30: 11355 | D30: 37587 | E30: 3694843.2 | F30: 3320250.7 | G30: 374595.19 | H30: 383011.1 | I30: 325.39 | J30: 0.11535608 | K30: 0.54496677
A31: Women's Apparel | B31: 21035 | C31: 17869 | D31: 62956 | E31: 3147800 | F31: 2828708.5 | G31: 319091.5 | H31: 350421.03 | I31: 176.16 | J31: 0.12388022 | K31: 0.54556691
A32: Water Sports | B32: 15540 | C32: 13758 | D32: 15540 | E32: 3113844.6 | F32: 2798044.1 | G32: 315800.5 | H32: 325146.96 | I32: 226.33 | J32: 0.11620509 | K32: 0.5480695
A33: Men's Footwear | B33: 22246 | C33: 18783 | D33: 22246 | E33: 2891757.5 | F33: 2598494.4 | G33: 293263.1 | H33: 311902.82 | I33: 153.96 | J33: 0.12003213 | K33: 0.544862
A34: Indoor/Outdoor Games | B34: 19298 | C34: 16623 | D34: 57803 | E34: 2888993.9 | F34: 2596454 | G34: 292550.63 | H34: 318451.43 | I34: 173.79 | J34: 0.12264859 | K34: 0.54746606
A35: Shop By Sport | B35: 10984 | C35: 10136 | D35: 32726 | E35: 1309522 | F35: 1177185.6 | G35: 132338.73 | H35: 129813.96 | I35: 129.2 | J35: 0.11027484 | K35: 0.5515295
A36: Computers | B36: 442 | C36: 442 | D36: 442 | E36: 663000 | F36: 595395 | G36: 67605 | H36: 69656.81 | I36: 1500 | J36: 0.1169926 | K36: 0.50678733
A37: Electronics | B37: 3156 | C37: 3061 | D37: 9436 | E37: 371034.64 | F37: 333327.26 | G37: 37708.03 | H37: 40891.38 | I37: 121.21 | J37: 0.12267638 | K37: 0.5608365
A38: Cameras | B38: 592 | C38: 592 | D38: 592 | E38: 267607.68 | F38: 240496.68 | G38: 27111 | H38: 30289.8 | I38: 452.04 | J38: 0.12594685 | K38: 0.58108108
... A41: Crafts | B41: 484 | C41: 484 | D41: 484 | E41: 223356.32 | F41: 200704.87 | G41: 22651.45 | H41: 25531.17 | I41: 461.48 | J41: 0.12720753 | K41: 0.55991736

Sheet Metrics Validation
A2: Metrics Validation
A3: Every headline claim is recalculated from the processed source
A5: metric | B5: resume_claim | C5: calculated_value | D5: definition | E5: result
A6: Total records | B6: 180K+ | C6: 180519 | D6: COUNT(*) | E6: Verified
A7: Distinct orders | B7: 65.7K | C7: 65752 | D7: COUNT(DISTINCT order_id) | E7: Correct value is 65,752 (65.75K; 65.8K to 1 decimal)
A8: Total sales | B8: $36.78M | C8: 36784734 | D8: SUM(gross_sales / source Sales) | E8: Verified as gross sales; net sales are $33.05M
A9: Total profit | B9: $3.97M | C9: 3966903 | D9: SUM(profit / source Order Profit Per Order) | E9: Verified
A10: Late-delivery rate | B10: 54.83% | C10: 0.54829132 | D10: SUM(late_delivery_risk) / COUNT(*) | E10: Verified at line-item row grain; order-level rate is 54.82%
A11: AOV | B11: $559.46 | C11: 559.44662 | D11: SUM(gross_sales) / COUNT(DISTINCT order_id) | E11: Correct two-decimal rounding is $559.45

Sheet Data Quality
A2: Data Quality Assessment
A3: Checks cover grain, completeness, monetary consistency, and operational fields
A5: check | B5: expected | C5: actual | D5: status | E5: interpretation
A6: Dataset rows | B6: 180519 | C6: 180519 | D6: Pass | E6: Line-item grain; Order Item Id is unique
A7: Dataset columns (raw) | B7: 53 | C7: 53 | D7: Pass | E7: 53 source columns
A8: Exact duplicate rows | B8: 0 | C8: 0 | D8: Pass | E8: No exact duplicates expected
A9: Unique Order Item Id | B9: 180519 | C9: 180519 | D9: Pass | E9: Candidate primary key
A10: Order date parse failures | B10: 0 | C10: 0 | D10: Pass | E10: Parsed as source-local timestamps
A11: Shipping date parse failures | B11: 0 | C11: 0 | D11: Pass | E11: Parsed as source-local timestamps
A12: Negative sales rows | B12: 0 | C12: 0 | D12: Pass | E12: Gross sales must be non-negative
A13: Negative quantity rows | B13: 0 | C13: 0 | D13: Pass | E13: Quantity must be non-negative
A14: Discount rate outside 0-1 | B14: 0 | C14: 0 | D14: Pass | E14: Rate domain check
A15: Late-risk/status mismatches | B15: 0 | C15: 0 | D15: Pass | E15: Risk flag agrees with delivery status
A16: Shipping before order rows | B16: 0 | C16: 0 | D16: Pass | E16: Temporal integrity
A17: Product description missing | B17: 180519 | C17: 180519 | D17: Documented | E17: Entirely empty; removed from cleaned file
A18: Order zipcode missing | C18: 155679 | D18: Documented | E18: 86.24% missing; removed from cleaned file
A19: Timestamp duration differs by 0.5 day | B19: 0 | C19: 9737 | D19: Documented | E19: Use supplied actual_shipping_days for KPI consistency

Sheet Dashboard Data
A1: KPI filter cube | Q1: Month | R1: Gross Sales ($M) | S1: Net Sales | T1: Profit | U1: Orders | V1: Late Delivery % | X1: Market | Y1: Gross Sales ($M) | AA1: Segment | AB1: Gross Sales ($M) | AD1: Shipping Mode | AE1: Late Delivery % | AG1: Category | AH1: Gross Sales ($M) | AJ1: Delivery Status | AK1: Orders
Q2: 2015-01 | R2: =SUMIFS($G$32:$G$423,$A$32:$A$423,Dashboard!$B$4,$B$32:$B$423,Dashboard!$E$4,$C$32:$C$423,Q2)/1000000 -> 1.0515901 | S2: =SUMIFS($H$32:$H$423,$A$32:$A$423,Dashboard!$B$4,$B$32:$B$423,Dashboard!$E$4,$C$32:$C$423,Q2) -> 945382.15 | T2: =SUMIFS($J$32:$J$423,$A$32:$A$423,Dashboard!$B$4,$B$32:$B$423,Dashboard!$E$4,$C$32:$C$423,Q2) -> 111660.74 | U2: =SUMIFS($E$32:$E$423,$A$32:$A$423,Dashboard!$B$4,$B$32:$B$423,Dashboard!$E$4,$C$32:$C$423,Q2) -> 1787 | V2: =IFERROR(SUMIFS($K$32:$K$423,$A$32:$A$423,Dashboard!$B$4,$B$32:$B$423,Dashboard!$E$4,$C$32:$C$423,Q2)/SUMIFS($D$32:$D$423,$A$32:$A$423,Dashboard!$B$4,$B$32:$B$423,Dashboard!$E$4,$C$32:$C$423,Q2),0) -> 0.54114994 | X2: Africa | Y2: 2.2944529 | AA2: Consumer | AB2: 19.09579 | AD2: First Class | AE2: 0.95267388 | AG2: Fishing | AH2: 6.9296535 | AJ2: Advance shipping | AK2: 15127
A3: market | B3: customer_segment | C3: records | D3: orders | E3: units | F3: gross_sales | G3: net_sales | H3: discount | I3: profit | J3: late_records | K3: gross_aov | L3: net_aov | M3: profit_margin_net | N3: late_delivery_rate_row | Q3: 2015-02 | R3: =SUMIFS($G$32:$G$423,$A$32:$A$423,Dashboard!$B$4,$B$32:$B$423,Dashboard!$E$4,$C$32:$C$423,Q3)/1000000 -> 0.92700988 | S3: =SUMIFS($H$32:$H$423,$A$32:$A$423,Dashboard!$B$4,$B$32:$B$423,Dashboard!$E$4,$C$32:$C$423,Q3) -> 833012.42 | T3: =SUMIFS($J$32:$J$423,$A$32:$A$423,Dashboard!$B$4,$B$32:$B$423,Dashboard!$E$4,$C$32:$C$423,Q3) -> 99140.66 | U3: =SUMIFS($E$32:$E$423,$A$32:$A$423,Dashboard!$B$4,$B$32:$B$423,Dashboard!$E$4,$C$32:$C$423,Q3) -> 1585 | V3: =IFERROR(SUMIFS($K$32:$K$423,$A$32:$A$423,Dashboard!$B$4,$B$32:$B$423,Dashboard!$E$4,$C$32:$C$423,Q3)/SUMIFS($D$32:$D$423,$A$32:$A$423,Dashboard!$B$4,$B$32:$B$423,Dashboard!$E$4,$C$32:$C$423,Q3),0) -> 0.54853034 | X3: Europe | Y3: 10.872397 | AA3: Corporate | AB3: 11.168407 | AD3: Second Class | AE3: 0.76717796 | AG3: Cleats | AH3: 4.4319427 | AJ3: Late delivery | AK3: 36048
A4: Africa | B4: All | C4: 11614 | D4: 3854 | E4: 25603 | F4: 2294452.9 | G4: 2061679.4 | H4: 232776.37 | I4: 252071.18 | J4: 6340 | K4: 595.34 | L4: 534.95 | M4: 0.12226498 | N4: 0.54589289 | Q4: 2015-03 | R4: =SUMIFS($G$32:$G$423,$A$32:$A$423,Dashboard!$B$4,$B$32:$B$423,Dashboard!$E$4,$C$32:$C$423,Q4)/1000000 -> 1.0512537 | S4: =SUMIFS($H$32:$H$423,$A$32:$A$423,Dashboard!$B$4,$B$32:$B$423,Dashboard!$E$4,$C$32:$C$423,Q4) -> 944050.1 | T4: =SUMIFS($J$32:$J$423,$A$32:$A$423,Dashboard!$B$4,$B$32:$B$423,Dashboard!$E$4,$C$32:$C$423,Q4) -> 113778.21 | U4: =SUMIFS($E$32:$E$423,$A$32:$A$423,Dashboard!$B$4,$B$32:$B$423,Dashboard!$E$4,$C$32:$C$423,Q4) -> 1781 | V4: =IFERROR(SUMIFS($K$32:$K$423,$A$32:$A$423,Dashboard!$B$4,$B$32:$B$423,Dashboard!$E$4,$C$32:$C$423,Q4)/SUMIFS($D$32:$D$423,$A$32:$A$423,Dashboard!$B$4,$B$32:$B$423,Dashboard!$E$4,$C$32:$C$423,Q4),0) -> 0.54755688 | X4: LATAM | Y4: 10.277613 | AA4: Home Office | AB4: 6.5205379 | AD4: Same Day | AE4: 0.46149538 | AG4: Camping & Hiking | AH4: 4.1184254 | AJ4: Shipping canceled | AK4: 2855
A5: Africa | B5: Consumer | C5: 6007 | D5: 2009 | E5: 13231 | F5: 1187434.1 | G5: 1066810.3 | H5: 120625.2 | I5: 129600.89 | J5: 3305 | K5: 591.06 | L5: 531.02 | M5: 0.12148448 | N5: 0.55019144 | Q5: 2015-04 | R5: =SUMIFS($G$32:$G$423,$A$32:$A$423,Dashboard!$B$4,$B$32:$B$423,Dashboard!$E$4,$C$32:$C$423,Q5)/1000000 -> 1.0144633 | S5: =SUMIFS($H$32:$H$423,$A$32:$A$423,Dashboard!$B$4,$B$32:$B$423,Dashboard!$E$4,$C$32:$C$423,Q5) -> 912004.39 | T5: =SUMIFS($J$32:$J$423,$A$32:$A$423,Dashboard!$B$4,$B$32:$B$423,Dashboard!$E$4,$C$32:$C$423,Q5) -> 108083.68 | U5: =SUMIFS($E$32:$E$423,$A$32:$A$423,Dashboard!$B$4,$B$32:$B$423,Dashboard!$E$4,$C$32:$C$423,Q5) -> 1710 | V5: =IFERROR(SUMIFS($K$32:$K$423,$A$32:$A$423,Dashboard!$B$4,$B$32:$B$423,Dashboard!$E$4,$C$32:$C$423,Q5)/SUMIFS($D$32:$D$423,$A$32:$A$423,Dashboard!$B$4,$B$32:$B$423,Dashboard!$E$4,$C$32:$C$423,Q5),0) -> 0.53843153 | X5: Pacific Asia | Y5: 8.2737436 | AD5: Standard Class | AE5: 0.3813193 | AG5: Cardio Equipment | AH5: 3.6948432 | AJ5: Shipping on time | AK5: 11722
A6: Africa | B6: Corporate | C6: 3528 | D6: 1167 | E6: 7671 | F6: 699757.5 | G6: 629263.86 | H6: 70494.45 | I6: 75761.37 | J6: 1943 | K6: 599.62 | L6: 539.21 | M6: 0.12039682 | N6: 0.55073696 | Q6: 2015-05 | R6: =SUMIFS($G$32:$G$423,$A$32:$A$423,Dashboard!$B$4,$B$32:$B$423,Dashboard!$E$4,$C$32:$C$423,Q6)/1000000 -> 1.0504784 | S6: =SUMIFS($H$32:$H$423,$A$32:$A$423,Dashboard!$B$4,$B$32:$B$423,Dashboard!$E$4,$C$32:$C$423,Q6) -> 943939.76 | T6: =SUMIFS($J$32:$J$423,$A$32:$A$423,Dashboard!$B$4,$B$32:$B$423,Dashboard!$E$4,$C$32:$C$423,Q6) -> 112147.9 | U6: =SUMIFS($E$32:$E$423,$A$32:$A$423,Dashboard!$B$4,$B$32:$B$423,Dashboard!$E$4,$C$32:$C$423,Q6) -> 1776 | V6: =IFERROR(SUMIFS($K$32:$K$423,$A$32:$A$423,Dashboard!$B$4,$B$32:$B$423,Dashboard!$E$4,$C$32:$C$423,Q6)/SUMIFS($D$32:$D$423,$A$32:$A$423,Dashboard!$B$4,$B$32:$B$423,Dashboard!$E$4,$C$32:$C$423,Q6),0) -> 0.55086802 | X6: USCA | Y6: 5.0665286 | AG6: Women's Apparel | AH6: 3.1478
A7: Africa | B7: Home Office | C7: 2079 | D7: 678 | E7: 4701 | F7: 407261.31 | G7: 365605.22 | H7: 41656.72 | I7: 46708.92 | J7: 1092 | K7: 600.68 | L7: 539.24 | M7: 0.1277578 | N7: 0.52525253 | Q7: 2015-06 | R7: =SUMIFS($G$32:$G$423,$A$32:$A$423,Dashboard!$B$4,$B$32:$B$423,Dashboard!$E$4,$C$32:$C$423,Q7)/1000000 -> 1.0240061 | S7: =SUMIFS($H$32:$H$423,$A$32:$A$423,Dashboard!$B$4,$B$32:$B$423,Dashboard!$E$4,$C$32:$C$423,Q7) -> 920242.05 | T7: =SUMIFS($J$32:$J$423,$A$32:$A$423,Dashboard!$B$4,$B$32:$B$423,Dashboard!$E$4,$C$32:$C$423,Q7) -> 110147.16 | U7: =SUMIFS($E$32:$E$423,$A$32:$A$423,Dashboard!$B$4,$B$32:$B$423,Dashboard!$E$4,$C$32:$C$423,Q7) -> 1725 | V7: =IFERROR(SUMIFS($K$32:$K$423,$A$32:$A$423,Dashboard!$B$4,$B$32:$B$423,Dashboard!$E$4,$C$32:$C$423,Q7)/SUMIFS($D$32:$D$423,$A$32:$A$423,Dashboard!$B$4,$B$32:$B$423,Dashboard!$E$4,$C$32:$C$423,Q7),0) -> 0.54109856 | AG7: Water Sports | AH7: 3.1138446
A8: All | B8: All | C8: 180519 | D8: 65752 | E8: 384079 | F8: 36784734 | G8: 33054402 | H8: 3730378.4 | I8: 3966903 | J8: 98977 | K8: 559.45 | L8: 502.71 | M8: 0.12001134 | N8: 0.54829132 | Q8: 2015-07 | R8: =SUMIFS($G$32:$G$423,$A$32:$A$423,Dashboard!$B$4,$B$32:$B$423,Dashboard!$E$4,$C$32:$C$423,Q8)/1000000 -> 1.0380812 | S8: =SUMIFS($H$32:$H$423,$A$32:$A$423,Dashboard!$B$4,$B$32:$B$423,Dashboard!$E$4,$C$32:$C$423,Q8) -> 932936.78 | T8: =SUMIFS($J$32:$J$423,$A$32:$A$423,Dashboard!$B$4,$B$32:$B$423,Dashboard!$E$4,$C$32:$C$423,Q8) -> 115624.06 | U8: =SUMIFS($E$32:$E$423,$A$32:$A$423,Dashboard!$B$4,$B$32:$B$423,Dashboard!$E$4,$C$32:$C$423,Q8) -> 1763 | V8: =IFERROR(SUMIFS($K$32:$K$423,$A$32:$A$423,Dashboard!$B$4,$B$32:$B$423,Dashboard!$E$4,$C$32:$C$423,Q8)/SUMIFS($D$32:$D$423,$A$32:$A$423,Dashboard!$B$4,$B$32:$B$423,Dashboard!$E$4,$C$32:$C$423,Q8),0) -> 0.55463295 | AG8: Men's Footwear | AH8: 2.8917575
A9: All | B9: Consumer | C9: 93504 | D9: 34119 | E9: 199234 | F9: 19095790 | G9: 17164278 | H9: 1931535.7 | I9: 2073487.7 | J9: 51248 | K9: 559.68 | L9: 503.07 | M9: 0.1208025 | N9: 0.5480835 | Q9: 2015-08 | R9: =SUMIFS($G$32:$G$423,$A$32:$A$423,Dashboard!$B$4,$B$32:$B$423,Dashboard!$E$4,$C$32:$C$423,Q9)/1000000 -> 1.0294947 | S9: =SUMIFS($H$32:$H$423,$A$32:$A$423,Dashboard!$B$4,$B$32:$B$423,Dashboard!$E$4,$C$32:$C$423,Q9) -> 925192.86 | T9: =SUMIFS($J$32:$J$423,$A$32:$A$423,Dashboard!$B$4,$B$32:$B$423,Dashboard!$E$4,$C$32:$C$423,Q9) -> 117979.77 | U9: =SUMIFS($E$32:$E$423,$A$32:$A$423,Dashboard!$B$4,$B$32:$B$423,Dashboard!$E$4,$C$32:$C$423,Q9) -> 1762 | V9: =IFERROR(SUMIFS($K$32:$K$423,$A$32:$A$423,Dashboard!$B$4,$B$32:$B$423,Dashboard!$E$4,$C$32:$C$423,Q9)/SUMIFS($D$32:$D$423,$A$32:$A$423,Dashboard!$B$4,$B$32:$B$423,Dashboard!$E$4,$C$32:$C$423,Q9),0) -> 0.55679879 | AG9: Indoor/Outdoor Games | AH9: 2.8889939
A10: All | B10: Corporate | C10: 54789 | D10: 19856 | E10: 116560 | F10: 11168407 | G10: 10030650 | H10: 1137770.7 | I10: 1202575 | J10: 29982 | K10: 562.47 | L10: 505.17 | M10: 0.11989004 | N10: 0.54722663 | Q10: 2015-09 | R10: =SUMIFS($G$32:$G$423,$A$32:$A$423,Dashboard!$B$4,$B$32:$B$423,Dashboard!$E$4,$C$32:$C$423,Q10)/1000000 -> 1.0183386 | S10: =SUMIFS($H$32:$H$423,$A$32:$A$423,Dashboard!$B$4,$B$32:$B$423,Dashboard!$E$4,$C$32:$C$423,Q10) -> 914522.36 | T10: =SUMIFS($J$32:$J$423,$A$32:$A$423,Dashboard!$B$4,$B$32:$B$423,Dashboard!$E$4,$C$32:$C$423,Q10) -> 113467.94 | U10: =SUMIFS($E$32:$E$423,$A$32:$A$423,Dashboard!$B$4,$B$32:$B$423,Dashboard!$E$4,$C$32:$C$423,Q10) -> 1706 | V10: =IFERROR(SUMIFS($K$32:$K$423,$A$32:$A$423,Dashboard!$B$4,$B$32:$B$423,Dashboard!$E$4,$C$32:$C$423,Q10)/SUMIFS($D$32:$D$423,$A$32:$A$423,Dashboard!$B$4,$B$32:$B$423,Dashboard!$E$4,$C$32:$C$423,Q10),0) -> 0.56692607
A11: All | B11: Home Office | C11: 32226 | D11: 11777 | E11: 68285 | F11: 6520537.9 | G11: 5859474 | H11: 661072 | I11: 690840.34 | J11: 17747 | K11: 553.67 | L11: 497.54 | M11: 0.11790142 | N11: 0.5507044 | Q11: 2015-10 | R11: =SUMIFS($G$32:$G$423,$A$32:$A$423,Dashboard!$B$4,$B$32:$B$423,Dashboard!$E$4,$C$32:$C$423,Q11)/1000000 -> 1.0491542 | S11: =SUMIFS($H$32:$H$423,$A$32:$A$423,Dashboard!$B$4,$B$32:$B$423,Dashboard!$E$4,$C$32:$C$423,Q11) -> 943131.09 | T11: =SUMIFS($J$32:$J$423,$A$32:$A$423,Dashboard!$B$4,$B$32:$B$423,Dashboard!$E$4,$C$32:$C$423,Q11) -> 101757.87 | U11: =SUMIFS($E$32:$E$423,$A$32:$A$423,Dashboard!$B$4,$B$32:$B$423,Dashboard!$E$4,$C$32:$C$423,Q11) -> 1775 | V11: =IFERROR(SUMIFS($K$32:$K$423,$A$32:$A$423,Dashboard!$B$4,$B$32:$B$423,Dashboard!$E$4,$C$32:$C$423,Q11)/SUMIFS($D$32:$D$423,$A$32:$A$423,Dashboard!$B$4,$B$32:$B$423,Dashboard!$E$4,$C$32:$C$423,Q11),0) -> 0.54809506
A12: Europe | B12: All | C12: 50252 | D12: 18561 | E12: 105238 | F12: 10872397 | G12: 9769198.2 | H12: 1103210.8 | I12: 1169443 | J12: 27743 | K12: 585.77 | L12: 526.33 | M12: 0.11970716 | N12: 0.55207753 | Q12: 2015-11 | R12: =SUMIFS($G$32:$G$423,$A$32:$A$423,Dashboard!$B$4,$B$32:$B$423,Dashboard!$E$4,$C$32:$C$423,Q12)/1000000 -> 1.0291202 | S12: =SUMIFS($H$32:$H$423,$A$32:$A$423,Dashboard!$B$4,$B$32:$B$423,Dashboard!$E$4,$C$32:$C$423,Q12) -> 924602.56 | T12: =SUMIFS($J$32:$J$423,$A$32:$A$423,Dashboard!$B$4,$B$32:$B$423,Dashboard!$E$4,$C$32:$C$423,Q12) -> 104427.36 | U12: =SUMIFS($E$32:$E$423,$A$32:$A$423,Dashboard!$B$4,$B$32:$B$423,Dashboard!$E$4,$C$32:$C$423,Q12) -> 1729 | V12: =IFERROR(SUMIFS($K$32:$K$423,$A$32:$A$423,Dashboard!$B$4,$B$32:$B$423,Dashboard!$E$4,$C$32:$C$423,Q12)/SUMIFS($D$32:$D$423,$A$32:$A$423,Dashboard!$B$4,$B$32:$B$423,Dashboard!$E$4,$C$32:$C$423,Q12),0) -> 0.54269341
A13: Europe | B13: Consumer | C13: 26108 | D13: 9639 | E13: 54869 | F13: 5671565.2 | G13: 5097709 | H13: 573862.58 | I13: 627099 | J13: 14527 | K13: 588.4 | L13: 528.86 | M13: 0.12301585 | N13: 0.55641949 | Q13: 2015-12 | R13: =SUMIFS($G$32:$G$423,$A$32:$A$423,Dashboard!$B$4,$B$32:$B$423,Dashboard!$E$4,$C$32:$C$423,Q13)/1000000 -> 1.0578409 | S13: =SUMIFS($H$32:$H$423,$A$32:$A$423,Dashboard!$B$4,$B$32:$B$423,Dashboard!$E$4,$C$32:$C$423,Q13) -> 950526.91 | T13: =SUMIFS($J$32:$J$423,$A$32:$A$423,Dashboard!$B$4,$B$32:$B$423,Dashboard!$E$4,$C$32:$C$423,Q13) -> 110641.55 | U13: =SUMIFS($E$32:$E$423,$A$32:$A$423,Dashboard!$B$4,$B$32:$B$423,Dashboard!$E$4,$C$32:$C$423,Q13) -> 1805 | V13: =IFERROR(SUMIFS($K$32:$K$423,$A$32:$A$423,Dashboard!$B$4,$B$32:$B$423,Dashboard!$E$4,$C$32:$C$423,Q13)/SUMIFS($D$32:$D$423,$A$32:$A$423,Dashboard!$B$4,$B$32:$B$423,Dashboard!$E$4,$C$32:$C$423,Q13),0) -> 0.54682554
A14: Europe | B14: Corporate | C14: 15313 | D14: 5617 | E14: 31920 | F14: 3303070.6 | G14: 2968303.7 | H14: 334770.71 | I14: 355412.12 | J14: 8290 | K14: 588.05 | L14: 528.45 | M14: 0.11973577 | N14: 0.54137008 | Q14: 2016-01 | R14: =SUMIFS($G$32:$G$423,$A$32:$A$423,Dashboard!$B$4,$B$32:$B$423,Dashboard!$E$4,$C$32:$C$423,Q14)/1000000 -> 1.0463082 | S14: =SUMIFS($H$32:$H$423,$A$32:$A$423,Dashboard!$B$4,$B$32:$B$423,Dashboard!$E$4,$C$32:$C$423,Q14) -> 940283.62 | T14: =SUMIFS($J$32:$J$423,$A$32:$A$423,Dashboard!$B$4,$B$32:$B$423,Dashboard!$E$4,$C$32:$C$423,Q14) -> 106780.95 | U14: =SUMIFS($E$32:$E$423,$A$32:$A$423,Dashboard!$B$4,$B$32:$B$423,Dashboard!$E$4,$C$32:$C$423,Q14) -> 1772 | V14: =IFERROR(SUMIFS($K$32:$K$423,$A$32:$A$423,Dashboard!$B$4,$B$32:$B$423,Dashboard!$E$4,$C$32:$C$423,Q14)/SUMIFS($D$32:$D$423,$A$32:$A$423,Dashboard!$B$4,$B$32:$B$423,Dashboard!$E$4,$C$32:$C$423,Q14),0) -> 0.55576453
A15: Europe | B15: Home Office | C15: 8831 | D15: 3305 | E15: 18449 | F15: 1897760.7 | G15: 1703185.5 | H15: 194577.46 | I15: 186931.84 | J15: 4926 | K15: 574.21 | L15: 515.34 | M15: 0.10975424 | N15: 0.55780772 | Q15: 2016-02 | R15: =SUMIFS($G$32:$G$423,$A$32:$A$423,Dashboard!$B$4,$B$32:$B$423,Dashboard!$E$4,$C$32:$C$423,Q15)/1000000 -> 0.96854283 | S15: =SUMIFS($H$32:$H$423,$A$32:$A$423,Dashboard!$B$4,$B$32:$B$423,Dashboard!$E$4,$C$32:$C$423,Q15) -> 870116.74 | T15: =SUMIFS($J$32:$J$423,$A$32:$A$423,Dashboard!$B$4,$B$32:$B$423,Dashboard!$E$4,$C$32:$C$423,Q15) -> 86809.49 | U15: =SUMIFS($E$32:$E$423,$A$32:$A$423,Dashboard!$B$4,$B$32:$B$423,Dashboard!$E$4,$C$32:$C$423,Q15) -> 1650 | V15: =IFERROR(SUMIFS($K$32:$K$423,$A$32:$A$423,Dashboard!$B$4,$B$32:$B$423,Dashboard!$E$4,$C$32:$C$423,Q15)/SUMIFS($D$32:$D$423,$A$32:$A$423,Dashboard!$B$4,$B$32:$B$423,Dashboard!$E$4,$C$32:$C$423,Q15),0) -> 0.54147936
A16: LATAM | B16: All | C16: 51594 | D16: 17181 | E16: 112942 | F16: 10277613 | G16: 9235762 | H16: 1041863.2 | I16: 1123321.6 | J16: 28044 | K16: 598.2 | L16: 537.56 | M16: 0.12162739 | N16: 0.54355158 | Q16: 2016-03 | R16: =SUMIFS($G$32:$G$423,$A$32:$A$423,Dashboard!$B$4,$B$32:$B$423,Dashboard!$E$4,$C$32:$C$423,Q16)/1000000 -> 1.0258531 | S16: =SUMIFS($H$32:$H$423,$A$32:$A$423,Dashboard!$B$4,$B$32:$B$423,Dashboard!$E$4,$C$32:$C$423,Q16) -> 921487.72 | T16: =SUMIFS($J$32:$J$423,$A$32:$A$423,Dashboard!$B$4,$B$32:$B$423,Dashboard!$E$4,$C$32:$C$423,Q16) -> 101259.99 | U16: =SUMIFS($E$32:$E$423,$A$32:$A$423,Dashboard!$B$4,$B$32:$B$423,Dashboard!$E$4,$C$32:$C$423,Q16) -> 1764 | V16: =IFERROR(SUMIFS($K$32:$K$423,$A$32:$A$423,Dashboard!$B$4,$B$32:$B$423,Dashboard!$E$4,$C$32:$C$423,Q16)/SUMIFS($D$32:$D$423,$A$32:$A$423,Dashboard!$B$4,$B$32:$B$423,Dashboard!$E$4,$C$32:$C$423,Q16),0) -> 0.55758157
A17: LATAM | B17: Consumer | C17: 26598 | D17: 8884 | E17: 58345 | F17: 5289638.7 | G17: 4754728.3 | H17: 534916.97 | I17: 568246.21 | J17: 14525 | K17: 595.41 | L17: 535.2 | M17: 0.11951181 | N17: 0.54609369 | Q17: 2016-04 | R17: =SUMIFS($G$32:$G$423,$A$32:$A$423,Dashboard!$B$4,$B$32:$B$423,Dashboard!$E$4,$C$32:$C$423,Q17)/1000000 -> 1.0012116 | S17: =SUMIFS($H$32:$H$423,$A$32:$A$423,Dashboard!$B$4,$B$32:$B$423,Dashboard!$E$4,$C$32:$C$423,Q17) -> 900492.91 | T17: =SUMIFS($J$32:$J$423,$A$32:$A$423,Dashboard!$B$4,$B$32:$B$423,Dashboard!$E$4,$C$32:$C$423,Q17) -> 114976.62 | U17: =SUMIFS($E$32:$E$423,$A$32:$A$423,Dashboard!$B$4,$B$32:$B$423,Dashboard!$E$4,$C$32:$C$423,Q17) -> 1706 | V17: =IFERROR(SUMIFS($K$32:$K$423,$A$32:$A$423,Dashboard!$B$4,$B$32:$B$423,Dashboard!$E$4,$C$32:$C$423,Q17)/SUMIFS($D$32:$D$423,$A$32:$A$423,Dashboard!$B$4,$B$32:$B$423,Dashboard!$E$4,$C$32:$C$423,Q17),0) -> 0.55228566
A18: LATAM | B18: Corporate | C18: 15699 | D18: 5184 | E18: 34457 | F18: 3139114.8 | G18: 2818496.7 | H18: 320621.94 | I18: 350573.82 | J18: 8453 | K18: 605.54 | L18: 543.69 | M18: 0.12438326 | N18: 0.53844194 | Q18: 2016-05 | R18: =SUMIFS($G$32:$G$423,$A$32:$A$423,Dashboard!$B$4,$B$32:$B$423,Dashboard!$E$4,$C$32:$C$423,Q18)/1000000 -> 1.0294002 | S18: =SUMIFS($H$32:$H$423,$A$32:$A$423,Dashboard!$B$4,$B$32:$B$423,Dashboard!$E$4,$C$32:$C$423,Q18) -> 924978.21 | T18: =SUMIFS($J$32:$J$423,$A$32:$A$423,Dashboard!$B$4,$B$32:$B$423,Dashboard!$E$4,$C$32:$C$423,Q18) -> 110716.12 | U18: =SUMIFS($E$32:$E$423,$A$32:$A$423,Dashboard!$B$4,$B$32:$B$423,Dashboard!$E$4,$C$32:$C$423,Q18) -> 1763 | V18: =IFERROR(SUMIFS($K$32:$K$423,$A$32:$A$423,Dashboard!$B$4,$B$32:$B$423,Dashboard!$E$4,$C$32:$C$423,Q18)/SUMIFS($D$32:$D$423,$A$32:$A$423,Dashboard!$B$4,$B$32:$B$423,Dashboard!$E$4,$C$32:$C$423,Q18),0) -> 0.55658242
A19: LATAM | B19: Home Office | C19: 9297 | D19: 3113 | E19: 20140 | F19: 1848859.2 | G19: 1662536.9 | H19: 186324.24 | I19: 204501.58 | J19: 5066 | K19: 593.92 | L19: 534.06 | M19: 0.12300574 | N19: 0.54490696 | Q19: 2016-06 | R19: =SUMIFS($G$32:$G$423,$A$32:$A$423,Dashboard!$B$4,$B$32:$B$423,Dashboard!$E$4,$C$32:$C$423,Q19)/1000000 -> 1.0030595 | S19: =SUMIFS($H$32:$H$423,$A$32:$A$423,Dashboard!$B$4,$B$32:$B$423,Dashboard!$E$4,$C$32:$C$423,Q19) -> 901448 | T19: =SUMIFS($J$32:$J$423,$A$32:$A$423,Dashboard!$B$4,$B$32:$B$423,Dashboard!$E$4,$C$32:$C$423,Q19) -> 104196.07 | U19: =SUMIFS($E$32:$E$423,$A$32:$A$423,Dashboard!$B$4,$B$32:$B$423,Dashboard!$E$4,$C$32:$C$423,Q19) -> 1690 | V19: =IFERROR(SUMIFS($K$32:$K$423,$A$32:$A$423,Dashboard!$B$4,$B$32:$B$423,Dashboard!$E$4,$C$32:$C$423,Q19)/SUMIFS($D$32:$D$423,$A$32:$A$423,Dashboard!$B$4,$B$32:$B$423,Dashboard!$E$4,$C$32:$C$423,Q19),0) -> 0.56846063
A20: Pacific Asia | B20: All | C20: 41260 | D20: 17577 | E20: 83680 | F20: 8273743.6 | G20: 7434262.6 | H20: 839493.31 | I20: 857753.44 | J20: 22712 | K20: 470.71 | L20: 422.95 | M20: 0.11537842 | N20: 0.55046049 | Q20: 2016-07 | R20: =SUMIFS($G$32:$G$423,$A$32:$A$423,Dashboard!$B$4,$B$32:$B$423,Dashboard!$E$4,$C$32:$C$423,Q20)/1000000 -> 1.0457156 | S20: =SUMIFS($H$32:$H$423,$A$32:$A$423,Dashboard!$B$4,$B$32:$B$423,Dashboard!$E$4,$C$32:$C$423,Q20) -> 939216.39 | T20: =SUMIFS($J$32:$J$423,$A$32:$A$423,Dashboard!$B$4,$B$32:$B$423,Dashboard!$E$4,$C$32:$C$423,Q20) -> 119941.72 | U20: =SUMIFS($E$32:$E$423,$A$32:$A$423,Dashboard!$B$4,$B$32:$B$423,Dashboard!$E$4,$C$32:$C$423,Q20) -> 1758 | V20: =IFERROR(SUMIFS($K$32:$K$423,$A$32:$A$423,Dashboard!$B$4,$B$32:$B$423,Dashboard!$E$4,$C$32:$C$423,Q20)/SUMIFS($D$32:$D$423,$A$32:$A$423,Dashboard!$B$4,$B$32:$B$423,Dashboard!$E$4,$C$32:$C$423,Q20),0) -> 0.51932139
A21: Pacific Asia | B21: Consumer | C21: 21284 | D21: 9078 | E21: 43386 | F21: 4286860.6 | G21: 3853807.2 | H21: 433059.84 | I21: 445629.43 | J21: 11592 | K21: 472.23 | L21: 424.52 | M21: 0.11563356 | N21: 0.54463447 | Q21: 2016-08 | R21: =SUMIFS($G$32:$G$423,$A$32:$A$423,Dashboard!$B$4,$B$32:$B$423,Dashboard!$E$4,$C$32:$C$423,Q21)/1000000 -> 1.0482002 | S21: =SUMIFS($H$32:$H$423,$A$32:$A$423,Dashboard!$B$4,$B$32:$B$423,Dashboard!$E$4,$C$32:$C$423,Q21) -> 942408.93 | T21: =SUMIFS($J$32:$J$423,$A$32:$A$423,Dashboard!$B$4,$B$32:$B$423,Dashboard!$E$4,$C$32:$C$423,Q21) -> 110729.54 | U21: =SUMIFS($E$32:$E$423,$A$32:$A$423,Dashboard!$B$4,$B$32:$B$423,Dashboard!$E$4,$C$32:$C$423,Q21) -> 1766 | V21: =IFERROR(SUMIFS($K$32:$K$423,$A$32:$A$423,Dashboard!$B$4,$B$32:$B$423,Dashboard!$E$4,$C$32:$C$423,Q21)/SUMIFS($D$32:$D$423,$A$32:$A$423,Dashboard!$B$4,$B$32:$B$423,Dashboard!$E$4,$C$32:$C$423,Q21),0) -> 0.55268091
... A27: USCA | B27: Home Office | C27: 4551 | D27: 1500 | E27: 9918 | F27: 895366.25 | G27: 804720.99 | H27: 90646.24 | I27: 98683.5 | J27: 2554 | K27: 596.91 | L27: 536.48 | M27: 0.1226307 | N27: 0.56119534 | Q27: 2017-02 | R27: =SUMIFS($G$32:$G$423,$A$32:$A$423,Dashboard!$B$4,$B$32:$B$423,Dashboard!$E$4,$C$32:$C$423,Q27)/1000000 -> 0.99253488 | S27: =SUMIFS($H$32:$H$423,$A$32:$A$423,Dashboard!$B$4,$B$32:$B$423,Dashboard!$E$4,$C$32:$C$423,Q27) -> 891924.28 | T27: =SUMIFS($J$32:$J$423,$A$32:$A$423,Dashboard!$B$4,$B$32:$B$423,Dashboard!$E$4,$C$32:$C$423,Q27) -> 115111.07 | U27: =SUMIFS($E$32:$E$423,$A$32:$A$423,Dashboard!$B$4,$B$32:$B$423,Dashboard!$E$4,$C$32:$C$423,Q27) -> 1614 | V27: =IFERROR(SUMIFS($K$32:$K$423,$A$32:$A$423,Dashboard!$B$4,$B$32:$B$423,Dashboard!$E$4,$C$32:$C$423,Q27)/SUMIFS($D$32:$D$423,$A$32:$A$423,Dashboard!$B$4,$B$32:$B$423,Dashboard!$E$4,$C$32:$C$423,Q27),0) -> 0.54667754
Q28: 2017-03 | R28: =SUMIFS($G$32:$G$423,$A$32:$A$423,Dashboard!$B$4,$B$32:$B$423,Dashboard!$E$4,$C$32:$C$423,Q28)/1000000 -> 1.0480048 | S28: =SUMIFS($H$32:$H$423,$A$32:$A$423,Dashboard!$B$4,$B$32:$B$423,Dashboard!$E$4,$C$32:$C$423,Q28) -> 942290.42 | T28: =SUMIFS($J$32:$J$423,$A$32:$A$423,Dashboard!$B$4,$B$32:$B$423,Dashboard!$E$4,$C$32:$C$423,Q28) -> 118688.9 | U28: =SUMIFS($E$32:$E$423,$A$32:$A$423,Dashboard!$B$4,$B$32:$B$423,Dashboard!$E$4,$C$32:$C$423,Q28) -> 1782 | V28: =IFERROR(SUMIFS($K$32:$K$423,$A$32:$A$423,Dashboard!$B$4,$B$32:$B$423,Dashboard!$E$4,$C$32:$C$423,Q28)/SUMIFS($D$32:$D$423,$A$32:$A$423,Dashboard!$B$4,$B$32:$B$423,Dashboard!$E$4,$C$32:$C$423,Q28),0) -> 0.55264634
A29: Monthly filter cube | Q29: 2017-04 | R29: =SUMIFS($G$32:$G$423,$A$32:$A$423,Dashboard!$B$4,$B$32:$B$423,Dashboard!$E$4,$C$32:$C$423,Q29)/1000000 -> 1.0383216 | S29: =SUMIFS($H$32:$H$423,$A$32:$A$423,Dashboard!$B$4,$B$32:$B$423,Dashboard!$E$4,$C$32:$C$423,Q29) -> 932318.19 | T29: =SUMIFS($J$32:$J$423,$A$32:$A$423,Dashboard!$B$4,$B$32:$B$423,Dashboard!$E$4,$C$32:$C$423,Q29) -> 115961.06 | U29: =SUMIFS($E$32:$E$423,$A$32:$A$423,Dashboard!$B$4,$B$32:$B$423,Dashboard!$E$4,$C$32:$C$423,Q29) -> 1739 | V29: =IFERROR(SUMIFS($K$32:$K$423,$A$32:$A$423,Dashboard!$B$4,$B$32:$B$423,Dashboard!$E$4,$C$32:$C$423,Q29)/SUMIFS($D$32:$D$423,$A$32:$A$423,Dashboard!$B$4,$B$32:$B$423,Dashboard!$E$4,$C$32:$C$423,Q29),0) -> 0.53779739
Q30: 2017-05 | R30: =SUMIFS($G$32:$G$423,$A$32:$A$423,Dashboard!$B$4,$B$32:$B$423,Dashboard!$E$4,$C$32:$C$423,Q30)/1000000 -> 1.1054853 | S30: =SUMIFS($H$32:$H$423,$A$32:$A$423,Dashboard!$B$4,$B$32:$B$423,Dashboard!$E$4,$C$32:$C$423,Q30) -> 993199.04 | T30: =SUMIFS($J$32:$J$423,$A$32:$A$423,Dashboard!$B$4,$B$32:$B$423,Dashboard!$E$4,$C$32:$C$423,Q30) -> 115014.64 | U30: =SUMIFS($E$32:$E$423,$A$32:$A$423,Dashboard!$B$4,$B$32:$B$423,Dashboard!$E$4,$C$32:$C$423,Q30) -> 1763 | V30: =IFERROR(SUMIFS($K$32:$K$423,$A$32:$A$423,Dashboard!$B$4,$B$32:$B$423,Dashboard!$E$4,$C$32:$C$423,Q30)/SUMIFS($D$32:$D$423,$A$32:$A$423,Dashboard!$B$4,$B$32:$B$423,Dashboard!$E$4,$C$32:$C$423,Q30),0) -> 0.53470002
A31: market | B31: customer_segment | C31: order_year_month | D31: records | E31: orders | F31: units | G31: gross_sales | H31: net_sales | I31: discount | J31: profit | K31: late_records | L31: gross_aov | M31: net_aov | N31: profit_margin_net | O31: late_delivery_rate_row | Q31: 2017-06 | R31: =SUMIFS($G$32:$G$423,$A$32:$A$423,Dashboard!$B$4,$B$32:$B$423,Dashboard!$E$4,$C$32:$C$423,Q31)/1000000 -> 1.0320865 | S31: =SUMIFS($H$32:$H$423,$A$32:$A$423,Dashboard!$B$4,$B$32:$B$423,Dashboard!$E$4,$C$32:$C$423,Q31) -> 927445.96 | T31: =SUMIFS($J$32:$J$423,$A$32:$A$423,Dashboard!$B$4,$B$32:$B$423,Dashboard!$E$4,$C$32:$C$423,Q31) -> 110399.29 | U31: =SUMIFS($E$32:$E$423,$A$32:$A$423,Dashboard!$B$4,$B$32:$B$423,Dashboard!$E$4,$C$32:$C$423,Q31) -> 1676 | V31: =IFERROR(SUMIFS($K$32:$K$423,$A$32:$A$423,Dashboard!$B$4,$B$32:$B$423,Dashboard!$E$4,$C$32:$C$423,Q31)/SUMIFS($D$32:$D$423,$A$32:$A$423,Dashboard!$B$4,$B$32:$B$423,Dashboard!$E$4,$C$32:$C$423,Q31),0) -> 0.53504343
A32: All | B32: All | C32: 2015-01 | D32: 5322 | E32: 1787 | F32: 11854 | G32: 1051590.1 | H32: 945382.15 | I32: 106209.28 | J32: 111660.74 | K32: 2880 | L32: 588.47 | M32: 529.03 | N32: 0.11811175 | O32: 0.54114994 | Q32: 2017-07 | R32: =SUMIFS($G$32:$G$423,$A$32:$A$423,Dashboard!$B$4,$B$32:$B$423,Dashboard!$E$4,$C$32:$C$423,Q32)/1000000 -> 1.1043733 | S32: =SUMIFS($H$32:$H$423,$A$32:$A$423,Dashboard!$B$4,$B$32:$B$423,Dashboard!$E$4,$C$32:$C$423,Q32) -> 992423.42 | T32: =SUMIFS($J$32:$J$423,$A$32:$A$423,Dashboard!$B$4,$B$32:$B$423,Dashboard!$E$4,$C$32:$C$423,Q32) -> 113026.7 | U32: =SUMIFS($E$32:$E$423,$A$32:$A$423,Dashboard!$B$4,$B$32:$B$423,Dashboard!$E$4,$C$32:$C$423,Q32) -> 1776 | V32: =IFERROR(SUMIFS($K$32:$K$423,$A$32:$A$423,Dashboard!$B$4,$B$32:$B$423,Dashboard!$E$4,$C$32:$C$423,Q32)/SUMIFS($D$32:$D$423,$A$32:$A$423,Dashboard!$B$4,$B$32:$B$423,Dashboard!$E$4,$C$32:$C$423,Q32),0) -> 0.54776232
A33: All | B33: All | C33: 2015-02 | D33: 4729 | E33: 1585 | F33: 10438 | G33: 927009.88 | H33: 833012.42 | I33: 93998.57 | J33: 99140.66 | K33: 2594 | L33: 584.86 | M33: 525.56 | N33: 0.11901462 | O33: 0.54853034 | Q33: 2017-08 | R33: =SUMIFS($G$32:$G$423,$A$32:$A$423,Dashboard!$B$4,$B$32:$B$423,Dashboard!$E$4,$C$32:$C$423,Q33)/1000000 -> 1.1093371 | S33: =SUMIFS($H$32:$H$423,$A$32:$A$423,Dashboard!$B$4,$B$32:$B$423,Dashboard!$E$4,$C$32:$C$423,Q33) -> 996507.87 | T33: =SUMIFS($J$32:$J$423,$A$32:$A$423,Dashboard!$B$4,$B$32:$B$423,Dashboard!$E$4,$C$32:$C$423,Q33) -> 131501.16 | U33: =SUMIFS($E$32:$E$423,$A$32:$A$423,Dashboard!$B$4,$B$32:$B$423,Dashboard!$E$4,$C$32:$C$423,Q33) -> 1768 | V33: =IFERROR(SUMIFS($K$32:$K$423,$A$32:$A$423,Dashboard!$B$4,$B$32:$B$423,Dashboard!$E$4,$C$32:$C$423,Q33)/SUMIFS($D$32:$D$423,$A$32:$A$423,Dashboard!$B$4,$B$32:$B$423,Dashboard!$E$4,$C$32:$C$423,Q33),0) -> 0.56437323
A34: All | B34: All | C34: 2015-03 | D34: 5362 | E34: 1781 | F34: 12062 | G34: 1051253.7 | H34: 944050.1 | I34: 107204.88 | J34: 113778.21 | K34: 2936 | L34: 590.26 | M34: 530.07 | N34: 0.12052137 | O34: 0.54755688 | Q34: 2017-09 | R34: =SUMIFS($G$32:$G$423,$A$32:$A$423,Dashboard!$B$4,$B$32:$B$423,Dashboard!$E$4,$C$32:$C$423,Q34)/1000000 -> 1.1437751 | S34: =SUMIFS($H$32:$H$423,$A$32:$A$423,Dashboard!$B$4,$B$32:$B$423,Dashboard!$E$4,$C$32:$C$423,Q34) -> 1027111.7 | T34: =SUMIFS($J$32:$J$423,$A$32:$A$423,Dashboard!$B$4,$B$32:$B$423,Dashboard!$E$4,$C$32:$C$423,Q34) -> 122462.39 | U34: =SUMIFS($E$32:$E$423,$A$32:$A$423,Dashboard!$B$4,$B$32:$B$423,Dashboard!$E$4,$C$32:$C$423,Q34) -> 1723 | V34: =IFERROR(SUMIFS($K$32:$K$423,$A$32:$A$423,Dashboard!$B$4,$B$32:$B$423,Dashboard!$E$4,$C$32:$C$423,Q34)/SUMIFS($D$32:$D$423,$A$32:$A$423,Dashboard!$B$4,$B$32:$B$423,Dashboard!$E$4,$C$32:$C$423,Q34),0) -> 0.54230102
A35: All | B35: All | C35: 2015-04 | D35: 5126 | E35: 1710 | F35: 11287 | G35: 1014463.3 | H35: 912004.39 | I35: 102460.16 | J35: 108083.68 | K35: 2760 | L35: 593.25 | M35: 533.34 | N35: 0.11851224 | O35: 0.53843153 | Q35: 2017-10 | R35: =SUMIFS($G$32:$G$423,$A$32:$A$423,Dashboard!$B$4,$B$32:$B$423,Dashboard!$E$4,$C$32:$C$423,Q35)/1000000 -> 1.0739942 | S35: =SUMIFS($H$32:$H$423,$A$32:$A$423,Dashboard!$B$4,$B$32:$B$423,Dashboard!$E$4,$C$32:$C$423,Q35) -> 966081.41 | T35: =SUMIFS($J$32:$J$423,$A$32:$A$423,Dashboard!$B$4,$B$32:$B$423,Dashboard!$E$4,$C$32:$C$423,Q35) -> 113447.17 | U35: =SUMIFS($E$32:$E$423,$A$32:$A$423,Dashboard!$B$4,$B$32:$B$423,Dashboard!$E$4,$C$32:$C$423,Q35) -> 2101 | V35: =IFERROR(SUMIFS($K$32:$K$423,$A$32:$A$423,Dashboard!$B$4,$B$32:$B$423,Dashboard!$E$4,$C$32:$C$423,Q35)/SUMIFS($D$32:$D$423,$A$32:$A$423,Dashboard!$B$4,$B$32:$B$423,Dashboard!$E$4,$C$32:$C$423,Q35),0) -> 0.53658537
A36: All | B36: All | C36: 2015-05 | D36: 5357 | E36: 1776 | F36: 11902 | G36: 1050478.4 | H36: 943939.76 | I36: 106539.92 | J36: 112147.9 | K36: 2951 | L36: 591.49 | M36: 531.5 | N36: 0.11880832 | O36: 0.55086802 | Q36: 2017-11 | R36: =SUMIFS($G$32:$G$423,$A$32:$A$423,Dashboard!$B$4,$B$32:$B$423,Dashboard!$E$4,$C$32:$C$423,Q36)/1000000 -> 0.62691437 | S36: =SUMIFS($H$32:$H$423,$A$32:$A$423,Dashboard!$B$4,$B$32:$B$423,Dashboard!$E$4,$C$32:$C$423,Q36) -> 563393.47 | T36: =SUMIFS($J$32:$J$423,$A$32:$A$423,Dashboard!$B$4,$B$32:$B$423,Dashboard!$E$4,$C$32:$C$423,Q36) -> 67791.25 | U36: =SUMIFS($E$32:$E$423,$A$32:$A$423,Dashboard!$B$4,$B$32:$B$423,Dashboard!$E$4,$C$32:$C$423,Q36) -> 2055 | V36: =IFERROR(SUMIFS($K$32:$K$423,$A$32:$A$423,Dashboard!$B$4,$B$32:$B$423,Dashboard!$E$4,$C$32:$C$423,Q36)/SUMIFS($D$32:$D$423,$A$32:$A$423,Dashboard!$B$4,$B$32:$B$423,Dashboard!$E$4,$C$32:$C$423,Q36),0) -> 0.55085158
A37: All | B37: All | C37: 2015-06 | D37: 5134 | E37: 1725 | F37: 11203 | G37: 1024006.2 | H37: 920242.05 | I37: 103765.36 | J37: 110147.16 | K37: 2778 | L37: 593.63 | M37: 533.47 | N37: 0.11969368 | O37: 0.54109856 | Q37: 2017-12 | R37: =SUMIFS($G$32:$G$423,$A$32:$A$423,Dashboard!$B$4,$B$32:$B$423,Dashboard!$E$4,$C$32:$C$423,Q37)/1000000 -> 0.50391081 | S37: =SUMIFS($H$32:$H$423,$A$32:$A$423,Dashboard!$B$4,$B$32:$B$423,Dashboard!$E$4,$C$32:$C$423,Q37) -> 452741.53 | T37: =SUMIFS($J$32:$J$423,$A$32:$A$423,Dashboard!$B$4,$B$32:$B$423,Dashboard!$E$4,$C$32:$C$423,Q37) -> 65837.63 | U37: =SUMIFS($E$32:$E$423,$A$32:$A$423,Dashboard!$B$4,$B$32:$B$423,Dashboard!$E$4,$C$32:$C$423,Q37) -> 2124 | V37: =IFERROR(SUMIFS($K$32:$K$423,$A$32:$A$423,Dashboard!$B$4,$B$32:$B$423,Dashboard!$E$4,$C$32:$C$423,Q37)/SUMIFS($D$32:$D$423,$A$32:$A$423,Dashboard!$B$4,$B$32:$B$423,Dashboard!$E$4,$C$32:$C$423,Q37),0) -> 0.55178908
A38: All | B38: All | C38: 2015-07 | D38: 5299 | E38: 1763 | F38: 11800 | G38: 1038081.2 | H38: 932936.78 | I38: 105145.67 | J38: 115624.06 | K38: 2939 | L38: 588.82 | M38: 529.18 | N38: 0.12393558 | O38: 0.55463295 | Q38: 2018-01 | R38: =SUMIFS($G$32:$G$423,$A$32:$A$423,Dashboard!$B$4,$B$32:$B$423,Dashboard!$E$4,$C$32:$C$423,Q38)/1000000 -> 0.33165011 | S38: =SUMIFS($H$32:$H$423,$A$32:$A$423,Dashboard!$B$4,$B$32:$B$423,Dashboard!$E$4,$C$32:$C$423,Q38) -> 297952.05 | T38: =SUMIFS($J$32:$J$423,$A$32:$A$423,Dashboard!$B$4,$B$32:$B$423,Dashboard!$E$4,$C$32:$C$423,Q38) -> 33841.89 | U38: =SUMIFS($E$32:$E$423,$A$32:$A$423,Dashboard!$B$4,$B$32:$B$423,Dashboard!$E$4,$C$32:$C$423,Q38) -> 2123 | V38: =IFERROR(SUMIFS($K$32:$K$423,$A$32:$A$423,Dashboard!$B$4,$B$32:$B$423,Dashboard!$E$4,$C$32:$C$423,Q38)/SUMIFS($D$32:$D$423,$A$32:$A$423,Dashboard!$B$4,$B$32:$B$423,Dashboard!$E$4,$C$32:$C$423,Q38),0) -> 0.56288271
A39: All | B39: All | C39: 2015-08 | D39: 5273 | E39: 1762 | F39: 11612 | G39: 1029494.7 | H39: 925192.86 | I39: 104303.01 | J39: 117979.77 | K39: 2936 | L39: 584.28 | M39: 525.08 | N39: 0.12751911 | O39: 0.55679879
A40: All | B40: All | C40: 2015-09 | D40: 5140 | E40: 1706 | F40: 11366 | G40: 1018338.6 | H40: 914522.36 | I40: 103817.56 | J40: 113467.94 | K40: 2914 | L40: 596.92 | M40: 536.06 | N40: 0.12407345 | O40: 0.56692607
A41: All | B41: All | C41: 2015-10 | D41: 5302 | E41: 1775 | F41: 11703 | G41: 1049154.2 | H41: 943131.09 | I41: 106024.42 | J41: 101757.87 | K41: 2906 | L41: 591.07 | M41: 531.34 | N41: 0.10789367 | O41: 0.54809506
A42: All | B42: All | C42: 2015-11 | D42: 5235 | E42: 1729 | F42: 11463 | G42: 1029120.2 | H42: 924602.56 | I42: 104518.97 | J42: 104427.36 | K42: 2841 | L42: 595.21 | M42: 534.76 | N42: 0.11294297 | O42: 0.54269341
A43: All | B43: All | C43: 2015-12 | D43: 5371 | E43: 1805 | F43: 11790 | G43: 1057840.9 | H43: 950526.91 | I43: 107315.25 | J43: 110641.55 | K43: 2937 | L43: 586.06 | M43: 526.61 | N43: 0.11640023 | O43: 0.54682554
A44: All | B44: All | C44: 2016-01 | D44: 5317 | E44: 1772 | F44: 11597 | G44: 1046308.2 | H44: 940283.62 | I44: 106025.88 | J44: 106780.95 | K44: 2955 | L44: 590.47 | M44: 530.63 | N44: 0.11356249 | O44: 0.55576453
A45: All | B45: All | C45: 2016-02 | D45: 4894 | E45: 1650 | F45: 10765 | G45: 968542.83 | H45: 870116.74 | I45: 98427.3 | J45: 86809.49 | K45: 2650 | L45: 587 | M45: 527.34 | N45: 0.099767636 | O45: 0.54147936
...

Sheet Data Dictionary
A2: Data Dictionary
A3: Original DataCo field definitions
A5: FIELDS | B5: DESCRIPTION
A6: Type | B6: : Type of transaction made
A7: Days for shipping (real) | B7: : Actual shipping days of the purchased product
A8: Days for shipment (scheduled) | B8: : Days of scheduled delivery of the purchased product
A9: Benefit per order | B9: : Earnings per order placed
A10: Sales per customer | B10: : Total sales per customer made per customer
A11: Delivery Status | B11: : Delivery status of orders: Advance shipping , Late delivery , Shipping canceled , Shipping on time
A12: Late_delivery_risk | B12: : Categorical variable that indicates if sending is late (1), it is not late (0).
A13: Category Id | B13: : Product category code
A14: Category Name | B14: : Description of the product category
A15: Customer City | B15: : City where the customer made the purchase
A16: Customer Country | B16: : Country where the customer made the purchase
... A57: Shipping Mode | B57: : The following shipping modes are presented : Standard Class , First Class , Second Class , Same Day
